Workbook

Sheet Assumptions
B1: GOATSAT · FINANCIAL MODEL ASSUMPTIONS · EUROPEAN HUB SCENARIO · CONSERVATIVE
B2: Parameter | C2: Conservative Value | D2: Type | E2: Notes, Sources & Conservative Rationale
B3: A · MACRO & JURISDICTION PARAMETERS
B4: Discount Rate / Hurdle Rate | C4: 0.0901 | D4: [INPUT] | E4: https://pages.stern.nyu.edu/~adamodar/New_Home_Page/datafile/wacc.html | G4: Damodaran
B5: Standard Corporate Income Tax Rate | C5: 0.1274 | D5: [INPUT] | E5: Blended European average: France 25.8%, Germany ~30.1%, Italy 24.0%. CONSERVATIVE: Using 25% blended. Verify per incorporation jurisdiction. Source: European Commission corporate tax surveys 2025.
B6: Preferential / R&D Credit Rate (net effective) | C6: 0.175 | D6: [INPUT] | E6: CONSERVATIVE: France CIR = 30% credit on R&D spend (reduces effective rate). Modeled as 17.5% net effective (25% CIT minus partial R&D credit). Set equal to standard rate above if no incentive applies in your jurisdiction.
B7: First Year Preferential Rate Applies (year #) | C7: 5 | D7: [INPUT] | E7: CONSERVATIVE: Pushed to Year 5 only — Year 4 EBIT is near breakeven ($-200k per report) so tax applies only when clearly profitable. Default = 5.
B8: Annual Inflation / OPEX Escalator | C8: 0.02 | D8: [INPUT] | E8: https://www.ecb.europa.eu/stats/macroeconomic_and_sectoral/hicp/html/index.en.html | G8: Damodaran
B9: Reporting Currency Label | C9: USD | D9: [INPUT] | E9: All values in USD. Revenue contracts in USD is standard for space hardware. Update label only — convert European payroll inputs at prevailing EUR/USD rate.
B10: B · REVENUE ASSUMPTIONS (all biased conservatively)
B11: Annual Adopter Licensing Fee (per manufacturer) | C11: 50000 | D11: [INPUT] | E11: CONSERVATIVE: Maintained at $50k/yr despite aerospace premium justification. HDMI LA benchmark: high-vol $10k/yr, low-vol $5k/yr (hdmi.org/register). GoatSat aerospace rate 5× HDMI floor — reasonable but adopters may negotiate down; do not increase this figure without a signed LOI.
B12: Module Royalty Rate | C12: 0.05 | D12: [INPUT] | E12: CONSERVATIVE: 4% (below report's 5% midpoint). Report range 3–7%. Prime contractors will push hard on royalty during early negotiations. At $500k avg module: $20k/module vs. $25k at 5%. Ref: Sisvel Wi-Fi 6 $1.20/unit; HEVC $0.20–$0.30 (via-la.com). Aerospace % model is correct — rate set at lower bound.
B13: Average Module Sale Price | C13: 450000 | D13: [INPUT] | E13: CONSERVATIVE: $450k vs. report's $500k. First-generation modules will be simpler (software-defined radios, sensor upgrades) commanding lower prices. Escalates toward $500k+ as ecosystem matures. Source: GomSpace, Endurosat catalog ranges.
B14: Certification Fee per New Adopter (one-time) | C14: 20000 | D14: [INPUT] | E14: CONSERVATIVE: $20k vs. $25k. AS9100 / DO-178C program analogues. Early adopters may receive discounted or waived certification to incentivize uptake.
B15: B1 · ADOPTER COUNT RAMP — CONSERVATIVE S-CURVE (slower than report)
B16: Year 1 — Adopting Manufacturers | C16: 0 | D16: [INPUT] | E16: Zero — standard in development, no licensing possible.
B17: Year 2 — Adopting Manufacturers | C17: 0 | D17: [INPUT] | E17: Zero — orbital demo phase, no commercial licensing.
B18: Year 3 — Adopting Manufacturers | C18: 3 | D18: [INPUT] | E18: CONSERVATIVE: 3 founding adopters vs. report's 5. Assumes one slippage and one deferred decision.
B19: Year 4 — Adopting Manufacturers | C19: 7 | D19: [INPUT] | E19: CONSERVATIVE: 7 vs. report's 10. Aerospace design cycles run 18–36 months; early adopters are designing next-gen bus, not retrofitting current one.
B20: Year 5 — Adopting Manufacturers | C20: 14 | D20: [INPUT] | E20: CONSERVATIVE: 14 vs. report's 20. S-curve inflection delayed by conservative sector risk aversion (ref: AS9100 rollout ~3–4yr cycle, CVG 2026).
B21: Year 6 — Adopting Manufacturers | C21: 25 | D21: [INPUT] | E21: [EXTRAP] S-curve mid-acceleration. Network effect beginning.
B22: Year 7 — Adopting Manufacturers | C22: 40 | D22: [INPUT] | E22: [EXTRAP] Standard becoming default for new microsatellite RFPs.
B23: Year 8 — Adopting Manufacturers | C23: 58 | D23: [INPUT] | E23: [EXTRAP] Near-dominant in 10–200kg class.
B24: Year 9 — Adopting Manufacturers | C24: 72 | D24: [INPUT] | E24: [EXTRAP] Approaching SAM saturation.
B25: Year 10 — Adopting Manufacturers | C25: 82 | D25: [INPUT] | E25: [EXTRAP] Full SAM penetration conservative ceiling — some manufacturers will maintain proprietary interfaces.
B26: B2 · MODULES SOLD PER YEAR — CONSERVATIVE RAMP
B27: Year 1 — Modules Sold | C27: 0 | D27: [INPUT] | E27: Zero — standard not yet published.
B28: Year 2 — Modules Sold | C28: 0 | D28: [INPUT] | E28: Zero — orbital demo only.
B29: Year 3 — Modules Sold | C29: 0 | D29: [INPUT] | E29: Zero — standard just launched. Pipeline forming but no sales.
B30: Year 4 — Modules Sold | C30: 30 | D30: [INPUT] | E30: CONSERVATIVE: 30 vs. report's 50. First modules are prototypes with limited commercial rollout; customers run qualification campaigns first.
B31: Year 5 — Modules Sold | C31: 120 | D31: [INPUT] | E31: CONSERVATIVE: 120 vs. report's 200. Ecosystem young; module vendors still building inventory and qualification flight heritage.
B32: Year 6 — Modules Sold | C32: 280 | D32: [INPUT] | E32: [EXTRAP] Growth accelerates as module catalog expands.
B33: Year 7 — Modules Sold | C33: 520 | D33: [INPUT] | E33: [EXTRAP] Network effect on module supply side.
B34: Year 8 — Modules Sold | C34: 850 | D34: [INPUT] | E34: [EXTRAP] Scale phase.
B35: Year 9 — Modules Sold | C35: 1200 | D35: [INPUT] | E35: [EXTRAP] Near-mature market.
B36: Year 10 — Modules Sold | C36: 1550 | D36: [INPUT] | E36: [EXTRAP] CONSERVATIVE ceiling: 1,550 vs. aggressive 2,000. Market constrained by satellite launch cadence and mission lifetimes.
B37: C · OPEX & CAPEX — EUROPEAN HUB (high-cost, conservative)
B38: Year 1 Engineering Payroll Base (EU Hub) | C38: 900000 | D38: [INPUT] | E38: CONSERVATIVE: $900k (above report's $750k floor). European aerospace engineer avg €57,500–€70,000/yr Germany (SalaryExpert 2026), €50,000–€62,000 France. 10-person nucleus at avg $90k/head incl. employer social charges (France ~45%, Germany ~21% on top of gross). Social charges are a major hidden cost in European employment — model must include them. Source: salaryexpert.com 2026.
B39: Engineering Payroll Annual Growth Rate | C39: 0.18 | D39: [INPUT] | E39: CONSERVATIVE: 18% (above report's implied ~20% but explicit here). Reflects headcount additions AND European wage inflation of 4% + merit increases. R&D headcount grows from 10 to ~20 by Year 5 per report.
B40: Year 1 IP & Legal Filings | C40: 200000 | D40: [INPUT] | E40: CONSERVATIVE: $200k vs. report's $150k. PCT international phase: $3,500–$5,500 (teakipservices.com). USPTO Jan-2025 utility: ~$2,000 (uspto.gov). EPO Apr-2026: search €1,595 + exam €2,010 + grant €1,135 (marks-clerk.com). Full patent family attorney fees: $15k–$50k per family (schellip.com). Year 1 assumed 3–4 patent families filed simultaneously = front-loaded cost.
...

Sheet FCF Model
B1: GOATSAT - 10-YEAR FREE CASH FLOW MODEL
B3: Phase | C3: Phase 1 R&D | D3: Phase 1/2 R&D+Demo | E3: Phase 2/3 Demo+Cert | F3: Phase 3/4 Cert+Scale | G3: Phase 4 Scale | H3: Phase 4 | I3: Phase 4 | J3: Phase 4 | K3: Phase 4 | L3: Phase 4 Mature | M3: 10-Yr Total
C4: 1 | D4: 2 | E4: 3 | F4: 4 | G4: 5 | H4: 6 | I4: 7 | J4: 8 | K4: 9 | L4: 10
B5: LINE ITEM | C5: Year 1 | D5: Year 2 | E5: Year 3 | F5: Year 4 | G5: Year 5 | H5: Year 6 | I5: Year 7 | J5: Year 8 | K5: Year 9 | L5: Year 10 | M5: TOTAL
B6: REVENUE
B7: Adopter Licensing Fees | C7: =Assumptions!C11*Assumptions!C16 -> 0 | D7: =Assumptions!C11*Assumptions!C17 -> 0 | E7: =Assumptions!C11*Assumptions!C18 -> 150000 | F7: =Assumptions!C11*Assumptions!C19 -> 350000 | G7: =Assumptions!C11*Assumptions!C20 -> 700000 | H7: =Assumptions!C11*Assumptions!C21 -> 1250000 | I7: =Assumptions!C11*Assumptions!C22 -> 2000000 | J7: =Assumptions!C11*Assumptions!C23 -> 2900000 | K7: =Assumptions!C11*Assumptions!C24 -> 3600000 | L7: =Assumptions!C11*Assumptions!C25 -> 4100000 | M7: =SUM(C6:L6) -> 0
B8: Module Royalties | C8: =Assumptions!C13*Assumptions!C12*Assumptions!C27 -> 0 | D8: =Assumptions!C13*Assumptions!C12*Assumptions!C28 -> 0 | E8: =Assumptions!C13*Assumptions!C12*Assumptions!C29 -> 0 | F8: =Assumptions!C13*Assumptions!C12*Assumptions!C30 -> 675000 | G8: =Assumptions!C13*Assumptions!C12*Assumptions!C31 -> 2700000 | H8: =Assumptions!C13*Assumptions!C12*Assumptions!C32 -> 6300000 | I8: =Assumptions!C13*Assumptions!C12*Assumptions!C33 -> 11700000 | J8: =Assumptions!C13*Assumptions!C12*Assumptions!C34 -> 19125000 | K8: =Assumptions!C13*Assumptions!C12*Assumptions!C35 -> 27000000 | L8: =Assumptions!C13*Assumptions!C12*Assumptions!C36 -> 34875000 | M8: =SUM(C7:L7) -> 15050000
B9: Certification Fees (on net new adopters) | C9: =Assumptions!C14*Assumptions!C16 -> 0 | D9: =MAX(0,Assumptions!C14*(Assumptions!C17-Assumptions!C16)) -> 0 | E9: =MAX(0,Assumptions!C14*(Assumptions!C18-Assumptions!C17)) -> 60000 | F9: =MAX(0,Assumptions!C14*(Assumptions!C19-Assumptions!C18)) -> 80000 | G9: =MAX(0,Assumptions!C14*(Assumptions!C20-Assumptions!C19)) -> 140000 | H9: =MAX(0,Assumptions!C14*(Assumptions!C21-Assumptions!C20)) -> 220000 | I9: =MAX(0,Assumptions!C14*(Assumptions!C22-Assumptions!C21)) -> 300000 | J9: =MAX(0,Assumptions!C14*(Assumptions!C23-Assumptions!C22)) -> 360000 | K9: =MAX(0,Assumptions!C14*(Assumptions!C24-Assumptions!C23)) -> 280000 | L9: =MAX(0,Assumptions!C14*(Assumptions!C25-Assumptions!C24)) -> 200000 | M9: =SUM(C8:L8) -> 102375000
B10: Non-Dilutive Grants (ESA BIC / Spark) | C10: =Assumptions!C57 -> 100000 | D10: =Assumptions!C58 -> 75000 | E10: =Assumptions!C59 -> 0 | F10: =Assumptions!C60 -> 0 | G10: =Assumptions!C61 -> 0 | H10: =Assumptions!C62 -> 0 | I10: =Assumptions!C63 -> 0 | J10: =Assumptions!C64 -> 0 | K10: =Assumptions!C65 -> 0 | L10: =Assumptions!C66 -> 0 | M10: =SUM(C9:L9) -> 1640000
B11: TOTAL GROSS REVENUE | C11: =C7+C8+C9+C10 -> 100000 | D11: =D7+D8+D9+D10 -> 75000 | E11: =E7+E8+E9+E10 -> 210000 | F11: =F7+F8+F9+F10 -> 1105000 | G11: =G7+G8+G9+G10 -> 3540000 | H11: =H7+H8+H9+H10 -> 7770000 | I11: =I7+I8+I9+I10 -> 14000000 | J11: =J7+J8+J9+J10 -> 22385000 | ... L11: =L7+L8+L9+L10 -> 39175000 | M11: =SUM(C10:L10) -> 175000
B12: OPERATING EXPENSES (OPEX) — EUROPEAN HUB RATES
B13: R&D / Engineering Payroll (EU Hub, incl. social charges) | C13: =Assumptions!C38 -> 900000 | D13: =C13*(1+Assumptions!C39) -> 1062000 | E13: =D13*(1+Assumptions!C39) -> 1253160 | F13: =E13*(1+Assumptions!C39) -> 1478728.8 | G13: =F13*(1+Assumptions!C39) -> 1744900 | H13: =G13*(1+Assumptions!C39) -> 2058982 | I13: =H13*(1+Assumptions!C39) -> 2429598.7 | J13: =I13*(1+Assumptions!C39) -> 2866926.5 | K13: =J13*(1+Assumptions!C39) -> 3382973.3 | L13: =K13*(1+Assumptions!C39) -> 3991908.5 | M13: =SUM(C12:L12) -> 0
B14: IP & Legal Filings (PCT / USPTO / EPO) | C14: =Assumptions!C40 -> 200000 | D14: =Assumptions!C40*0.65 -> 130000 | E14: =Assumptions!C40*0.3 -> 60000 | F14: =Assumptions!C40*0.3*(1+Assumptions!C8*(4-3)) -> 61200 | G14: =Assumptions!C40*0.3*(1+Assumptions!C8*(5-3)) -> 62400 | H14: =Assumptions!C40*0.3*(1+Assumptions!C8*(6-3)) -> 63600 | I14: =Assumptions!C40*0.3*(1+Assumptions!C8*(7-3)) -> 64800 | J14: =Assumptions!C40*0.3*(1+Assumptions!C8*(8-3)) -> 66000 | K14: =Assumptions!C40*0.3*(1+Assumptions!C8*(9-3)) -> 67200 | L14: =Assumptions!C40*0.3*(1+Assumptions!C8*(10-3)) -> 68400 | M14: =SUM(C13:L13) -> 21169178
B15: SG&A & Ecosystem Marketing | C15: =Assumptions!C41 -> 150000 | D15: =C15*(1+Assumptions!C42) -> 187500 | E15: =D15*(1+Assumptions!C42) -> 234375 | F15: =E15*(1+Assumptions!C42) -> 292968.75 | G15: =F15*(1+Assumptions!C42) -> 366210.94 | H15: =G15*(1+Assumptions!C42) -> 457763.67 | I15: =H15*(1+Assumptions!C42) -> 572204.59 | J15: =I15*(1+Assumptions!C42) -> 715255.74 | K15: =J15*(1+Assumptions!C42) -> 894069.67 | L15: =K15*(1+Assumptions!C42) -> 1117587.1 | M15: =SUM(C14:L14) -> 843600
B16: TOTAL OPEX | C16: =C13+C14+C15 -> 1250000 | D16: =D13+D14+D15 -> 1379500 | E16: =E13+E14+E15 -> 1547535 | F16: =F13+F14+F15 -> 1832897.5 | G16: =G13+G14+G15 -> 2173510.9 | H16: =H13+H14+H15 -> 2580345.7 | I16: =I13+I14+I15 -> 3066603.3 | J16: =J13+J14+J15 -> 3648182.2 | ... L16: =L13+L14+L15 -> 5177895.6 | M16: =SUM(C15:L15) -> 4987935.4
B17: PROFITABILITY
B18: EBITDA | C18: =C11-C16 -> -1150000 | D18: =D11-D16 -> -1304500 | E18: =E11-E16 -> -1337535 | F18: =F11-F16 -> -727897.55 | G18: =G11-G16 -> 1366489.1 | H18: =H11-H16 -> 5189654.3 | I18: =I11-I16 -> 10933397 | J18: =J11-J16 -> 18736818 | ... L18: =L11-L16 -> 33997104 | M18: =SUM(C17:L17) -> 0
B19: Depreciation & Amortization (D&A) | C19: =Assumptions!C43+Assumptions!C44*(1-1) -> 25000 | D19: =Assumptions!C43+Assumptions!C44*(2-1) -> 50000 | E19: =Assumptions!C43+Assumptions!C44*(3-1) -> 75000 | F19: =Assumptions!C43+Assumptions!C44*(4-1) -> 100000 | G19: =Assumptions!C43+Assumptions!C44*(5-1) -> 125000 | H19: =Assumptions!C43+Assumptions!C44*(6-1) -> 150000 | I19: =Assumptions!C43+Assumptions!C44*(7-1) -> 175000 | J19: =Assumptions!C43+Assumptions!C44*(8-1) -> 200000 | K19: =Assumptions!C43+Assumptions!C44*(9-1) -> 225000 | L19: =Assumptions!C43+Assumptions!C44*(10-1) -> 250000
B20: EBIT (Operating Profit) | C20: =C18-C19 -> -1175000 | D20: =D18-D19 -> -1354500 | E20: =E18-E19 -> -1412535 | F20: =F18-F19 -> -827897.55 | G20: =G18-G19 -> 1241489.1 | H20: =H18-H19 -> 5039654.3 | I20: =I18-I19 -> 10758397 | J20: =J18-J19 -> 18536818 | ... L20: =L18-L19 -> 33747104 | M20: =SUM(C19:L19) -> 1375000
B21: Operational Tax (Standard until Year in Assumptions, then R&D Credit Rate) | C21: =IF(1>=Assumptions!C7,MAX(0,C20)*Assumptions!C6,MAX(0,C20)*Assumptions!C5) -> 0 | D21: =IF(2>=Assumptions!C7,MAX(0,D20)*Assumptions!C6,MAX(0,D20)*Assumptions!C5) -> 0 | E21: =IF(3>=Assumptions!C7,MAX(0,E20)*Assumptions!C6,MAX(0,E20)*Assumptions!C5) -> 0 | F21: =IF(4>=Assumptions!C7,MAX(0,F20)*Assumptions!C6,MAX(0,F20)*Assumptions!C5) -> 0 | G21: =IF(5>=Assumptions!C7,MAX(0,G20)*Assumptions!C6,MAX(0,G20)*Assumptions!C5) -> 217260.59 | H21: =IF(6>=Assumptions!C7,MAX(0,H20)*Assumptions!C6,MAX(0,H20)*Assumptions!C5) -> 881939.51 | I21: =IF(7>=Assumptions!C7,MAX(0,I20)*Assumptions!C6,MAX(0,I20)*Assumptions!C5) -> 1882719.4 | J21: =IF(8>=Assumptions!C7,MAX(0,J20)*Assumptions!C6,MAX(0,J20)*Assumptions!C5) -> 3243943.1 | K21: =IF(9>=Assumptions!C7,MAX(0,K20)*Assumptions!C6,MAX(0,K20)*Assumptions!C5) -> 4604382.5 | L21: =IF(10>=Assumptions!C7,MAX(0,L20)*Assumptions!C6,MAX(0,L20)*Assumptions!C5) -> 5905743.3 | M21: =SUM(C20:L20) -> 90864287
B22: NOPAT (Net Operating Profit After Tax) | C22: =C20-C21 -> -1175000 | D22: =D20-D21 -> -1354500 | E22: =E20-E21 -> -1412535 | F22: =F20-F21 -> -827897.55 | G22: =G20-G21 -> 1024228.5 | H22: =H20-H21 -> 4157714.8 | I22: =I20-I21 -> 8875677.3 | J22: =J20-J21 -> 15292875 | ... L22: =L20-L21 -> 27841361 | M22: =SUM(C21:L21) -> 16735988
B23: FREE CASH FLOW (FCL) BRIDGE
B24: Add Back: D&A (non-cash charge) | C24: =C19 -> 25000 | D24: =D19 -> 50000 | E24: =E19 -> 75000 | F24: =F19 -> 100000 | G24: =G19 -> 125000 | H24: =H19 -> 150000 | I24: =I19 -> 175000 | J24: =J19 -> 200000 | ... L24: =L19 -> 250000
B25: Less: Capital Expenditures (CapEx) | C25: =-Assumptions!C46 -> -250000 | D25: =-Assumptions!C47 -> -1100000 | E25: =-Assumptions!C48 -> -350000 | F25: =-Assumptions!C49 -> -150000 | G25: =-Assumptions!C50 -> -175000 | H25: =-Assumptions!C51 -> -200000 | I25: =-Assumptions!C52 -> -225000 | J25: =-Assumptions!C53 -> -225000 | K25: =-Assumptions!C54 -> -225000 | L25: =-Assumptions!C55 -> -225000 | M25: =SUM(C24:L24) -> 1375000
B26: Less: Change in Working Capital (ΔWK) | C26: =-Assumptions!C69*C11 -> -12000 | D26: =-Assumptions!C69*MAX(0,D11-C11) -> 0 | E26: =-Assumptions!C69*MAX(0,E11-D11) -> -16200 | F26: =-Assumptions!C69*MAX(0,F11-E11) -> -107400 | G26: =-Assumptions!C69*MAX(0,G11-F11) -> -292200 | H26: =-Assumptions!C69*MAX(0,H11-G11) -> -507600 | I26: =-Assumptions!C69*MAX(0,I11-H11) -> -747600 | J26: =-Assumptions!C69*MAX(0,J11-I11) -> -1006200 | K26: =-Assumptions!C69*MAX(0,K11-J11) -> -1019400 | L26: =-Assumptions!C69*MAX(0,L11-K11) -> -995400 | M26: =SUM(C25:L25) -> -3125000
B27: FLUJO DE CAJA LIBRE / FREE CASH FLOW (FCF) | C27: =C22+C24+C25+C26 -> -1412000 | D27: =D22+D24+D25+D26 -> -2404500 | E27: =E22+E24+E25+E26 -> -1703735 | F27: =F22+F24+F25+F26 -> -985297.55 | G27: =G22+G24+G25+G26 -> 682028.49 | H27: =H22+H24+H25+H26 -> 3600114.8 | I27: =I22+I24+I25+I26 -> 8078077.3 | J27: =J22+J24+J25+J26 -> 14261675 | ... L27: =L22+L24+L25+L26 -> 26870961 | M27: =SUM(C26:L26) -> -4704000
B28: Cumulative FCF (tracks valley of death) | C28: =C27 -> -1412000 | D28: =C28+D27 -> -3816500 | E28: =D28+E27 -> -5520235 | F28: =E28+F27 -> -6505532.5 | G28: =F28+G27 -> -5823504.1 | H28: =G28+H27 -> -2223389.2 | I28: =H28+I27 -> 5854688 | J28: =I28+J27 -> 20116363 | K28: =J28+K27 -> 40803337 | L28: =K28+L27 -> 67674298
B29: FCF con VDT | C29: =C27/(1+Assumptions!$C$4)^C4 -> -1295294 | D29: =D27/(1+Assumptions!$C$4)^D4 -> -2023448.3 | E29: =E27/(1+Assumptions!$C$4)^E4 -> -1315234 | F29: =F27/(1+Assumptions!$C$4)^F4 -> -697753.53 | G29: =G27/(1+Assumptions!$C$4)^G4 -> 443068.44 | H29: =H27/(1+Assumptions!$C$4)^H4 -> 2145449.6 | I29: =I27/(1+Assumptions!$C$4)^I4 -> 4416148.1 | J29: =J27/(1+Assumptions!$C$4)^J4 -> 7152202.6 | ... L29: =L27/(1+Assumptions!$C$4)^L4 -> 11340176
B30: FCL - Con valor terminal (Graficar Este) | C30: =C27 -> -1412000 | D30: =D27 -> -2404500 | E30: =E27 -> -1703735 | F30: =F27 -> -985297.55 | G30: =G27 -> 682028.49 | H30: =H27 -> 3600114.8 | I30: =I27 -> 8078077.3 | J30: =J27 -> 14261675 | K30: =K27 -> 20686975 | L30: =L27+M47 -> 4.178607e+08
B32: ★FINANCIAL HEALTH INDICATORS - Derived from FCF above (all formulas reference Assumptions sheet)
B33: Terminal Value (Year 10 EBITDA × Conservative Multiple from Assumptions) | E33: =M50 -> 1.6515829e+08
B34: VPN / NPV — Valor Presente Neto | E34: =NPV(Assumptions!C4,C30:L30) -> 1.9468916e+08 | H34: TIR W/O Perpetuiry
B35: TIR / IRR — Tasa Interna de Retorno | E35: =IRR(C30:L30) -> 0.76826186 | H35: =IRR(C30:K30) -> 0.41756094
B36: PayBack — First Year Cumulative FCF Turns Positive | E36: Año 7
B37: Costo de Oportunidad / Discount Rate (from Assumptions A) | E37: =Assumptions!C4 -> 0.0901
B38: Max Drawdown — Total Capital Required Before Breakeven | E38: =MIN(C28,D28,E28,F28,G28) -> -6505532.5
B44: VPN / NPV — Valor Presente Neto | E44: =NPV(Assumptions!C4,C30:L30) -> 1.9468916e+08
M45: 2% Inflation
M46: =L27*(1+2%) -> 27408380 | N46: Gordon Shapiro
M47: =M46/(Assumptions!C4-2%) -> 3.9098973e+08 | N47: Supone que la empresa seguirá creciendo a una tasa constante
...
